<?xml version='1.0'?>
<sdf version='1.5'>
  <model name='tilt_rotor'>
    <pose>0 0 0.246 0 0 0</pose>
    <link name='base_link'>
      <pose>0 0 0 0 0 0</pose>
      <inertial>
        <pose frame=''>-0.12786 -4e-06 -0.005044 0 -0 0</pose>
        <mass>0.90187</mass>
        <inertia>
	  <ixx>0.197563</ixx>
          <ixy>0</ixy>
          <ixz>0</ixz>
          <iyy>0.1458929</iyy>
          <iyz>0</iyz>
          <izz>0.1477</izz>
        </inertia>
      </inertial>
      <collision name='base_link_collision'>
        <pose>-0.01 0 -0.08 0 0 0</pose>
        <geometry>
	   <mesh>
            <scale>1 1 1</scale>
            <uri>model://tilt_rotor/meshes/base_link.STL</uri>
          </mesh>
        </geometry>
	<surface>
          <contact>
            <ode>
              <max_vel>10</max_vel>
              <min_depth>0.01</min_depth>
            </ode>
          </contact>
          <!--<friction>
            <ode/>
          </friction>-->
        </surface>
      </collision>
      <visual name='base_link_visual'>
        <pose>0 0 0 0 -0 0</pose>
        <geometry>
          <mesh>
            <scale>1 1 1</scale>
            <uri>model://tilt_rotor/meshes/base_link.STL</uri>
          </mesh>
        </geometry>
        <material>
          <script>
            <name>Gazebo/Red</name>
            <uri>__default__</uri>
          </script>
        </material>
      </visual>

      <gravity>1</gravity>
      <velocity_decay/>
      <self_collide>0</self_collide>
    </link>

    
    <link name='servo_motor_front_right'>
      <pose frame=''>0.168 -0.20986 0.003 0 -0 0</pose>
      <inertial>
        <pose frame=''>-0 -0.015 0.030513 0 -0 0</pose>
        <mass>0.061036</mass>
        <inertia>
          <ixx>8.5593e-06</ixx>
          <ixy>3.1994e-23</ixy>
          <ixz>3.4129e-22</ixz>
          <iyy>7.1825e-06</iyy>
          <iyz>3.6464e-21</iyz>
          <izz>4.223e-06</izz>
        </inertia>
      </inertial>
      <collision name='servo_motor_front_right_collision'>
        <pose frame=''>0 0 0 0 -0 0</pose>
        <geometry>
          <mesh>
            <scale>1 1 1</scale>
            <uri>model://tilt_rotor/meshes/motor_front_right.STL</uri>
          </mesh>
        </geometry>
      </collision>
      <visual name='servo_motor_front_right_visual'>
        <pose frame=''>0 0 0 0 -0 0</pose>
        <geometry>
          <mesh>
            <scale>1 1 1</scale>
            <uri>model://tilt_rotor/meshes/motor_front_right.STL</uri>
          </mesh>
        </geometry>
      </visual>
    </link>
    <joint name='servo_front_right_joint' type='revolute'>
      <child>servo_motor_front_right</child>
      <parent>base_link</parent>
      <axis>
        <xyz>0 1 0</xyz>
        <limit>
          <lower>-0.017453</lower>
          <upper>1.5708</upper>
        </limit>
        <dynamics>
          <spring_reference>0</spring_reference>
          <spring_stiffness>0</spring_stiffness>
        </dynamics>
        <use_parent_model_frame>1</use_parent_model_frame>
	
      </axis>
    </joint>
    <link name='servo_motor_front_left'>
      <pose frame=''>0.168 0.20986 0.003 0 -0 0</pose>
      <inertial>
        <pose frame=''>0 0.015 0.030513 0 -0 0</pose>
        <mass>0.061036</mass>
        <inertia>
          <ixx>8.5593e-06</ixx>
          <ixy>-3.4497e-22</ixy>
          <ixz>-9.3615e-23</ixz>
          <iyy>7.1825e-06</iyy>
          <iyz>9.892e-21</iyz>
          <izz>4.223e-06</izz>
        </inertia>
      </inertial>
      <collision name='servo_motor_front_left_collision'>
        <pose frame=''>0 0 0 0 -0 0</pose>
        <geometry>
          <mesh>
            <scale>1 1 1</scale>
            <uri>model://tilt_rotor/meshes/motor_front_left.STL</uri>
          </mesh>
        </geometry>
      </collision>
      <visual name='servo_motor_front_left_visual'>
        <pose frame=''>0 0 0 0 -0 0</pose>
        <geometry>
          <mesh>
            <scale>1 1 1</scale>
            <uri>model://tilt_rotor/meshes/motor_front_left.STL</uri>
          </mesh>
        </geometry>
      </visual>
    </link>
    <joint name='servo_front_left_joint' type='revolute'>
      <child>servo_motor_front_left</child>
      <parent>base_link</parent>
      <axis>
        <xyz>0 1 0</xyz>
        <limit>
          <lower>-0.017453</lower>
          <upper>1.5708</upper>
        </limit>
        <dynamics>
          <spring_reference>0</spring_reference>
          <spring_stiffness>0</spring_stiffness>
        </dynamics>
        <use_parent_model_frame>1</use_parent_model_frame>
      </axis>
    </joint>
    <link name='tilt_rotor/imu_link'>
      <pose>0 0 0 0 0 0</pose>
      <inertial>
        <pose>0 0 0 0 0 0</pose>
        <mass>0.015</mass>
        <inertia>
          <ixx>1e-05</ixx>
          <ixy>0</ixy>
          <ixz>0</ixz>
          <iyy>1e-05</iyy>
          <iyz>0</iyz>
          <izz>1e-05</izz>
        </inertia>
      </inertial>
      <sensor name="imu_sensor" type="imu">
        <pose>0 0 0 3.141593 0 0</pose>
        <always_on>1</always_on>
        <update_rate>1000.0</update_rate>
      </sensor>
    </link>
    <joint name='tilt_rotor/imu_joint' type='revolute'>
      <child>tilt_rotor/imu_link</child>
      <parent>base_link</parent>
      <axis>
        <xyz>1 0 0</xyz>
        <limit>
          <lower>0</lower>
          <upper>0</upper>
          <effort>0</effort>
          <velocity>0</velocity>
        </limit>
        <dynamics>
          <spring_reference>0</spring_reference>
          <spring_stiffness>0</spring_stiffness>
        </dynamics>
        <use_parent_model_frame>1</use_parent_model_frame>
      </axis>
    </joint>

    <link name='ruddervator_left'>
      <pose frame=''>-0.775 0.11193 0.11193 -0.79348 0.12648 -0.1275</pose>
      <inertial>
        <pose frame=''>-0.009877 0.010141 -0.001818 0 -0 0</pose>
        <mass>0.0013457</mass>
        <inertia>
          <ixx>8.7475e-06</ixx>
          <ixy>8.2912e-15</ixy>
          <ixz>-2.1964e-08</ixz>
          <iyy>1.3526e-07</iyy>
          <iyz>-3.8536e-14</iyz>
          <izz>8.8628e-06</izz>
        </inertia>
      </inertial>
      <visual name='ruddervator_left_visual'>
        <pose frame=''>0 0 0 0 -0 0</pose>
        <geometry>
          <mesh>
            <scale>1 1 1</scale>
            <uri>model://tilt_rotor/meshes/ruddervator_left.STL</uri>
          </mesh>
        </geometry>
	<material>
          <script>
            <name>Gazebo/Yellow</name>
            <uri>__default__</uri>
          </script>
        </material>
      </visual>
    </link>
    <joint name='ruddervator_left_joint' type='revolute'>
      <child>ruddervator_left</child>
      <parent>base_link</parent>
      <axis>
        <xyz>-2e-06 0.707109 -0.707105</xyz>
        <limit>
          <lower>-0.5236</lower>
          <upper>0.5236</upper>
        </limit>
        <dynamics>
          <damping>1.000</damping>
        </dynamics>
	<use_parent_model_frame>1</use_parent_model_frame>
      </axis>
      <physics>
        <ode>
          <implicit_spring_damper>1</implicit_spring_damper>
        </ode>
      </physics>
    </joint>

    <link name='ruddervator_right'>
      <pose frame=''>-0.775 -0.11193 0.11193 0.7854 0.003309 0.003309</pose>
      <inertial>
        <pose frame=''>-0.010043 -0.010141 9.2e-05 0 -0 0</pose>
        <mass>0.0013457</mass>
        <inertia>
          <ixx>8.74347e-06</ixx>
          <ixy>-1.54079e-15</ixy>
          <ixz>1.13388e-09</ixz>
          <iyy>1.35259e-07</iyy>
          <iyz>-3.93914e-14</iyz>
          <izz>8.86684e-06</izz>
        </inertia>
      </inertial>
      <visual name='ruddervator_right_visual'>
        <pose frame=''>0 0 0 0 -0 0</pose>
        <geometry>
          <mesh>
            <scale>1 1 1</scale>
            <uri>model://tilt_rotor/meshes/ruddervator_right.STL</uri>
          </mesh>
        </geometry>
	<material>
          <script>
            <name>Gazebo/Yellow</name>
            <uri>__default__</uri>
          </script>
        </material>
      </visual>
    </link>
    <joint name='ruddervator_right_joint' type='revolute'>
      <child>ruddervator_right</child>
      <parent>base_link</parent>
      <axis>
        <xyz>-0 0.707109 0.707104</xyz>
        <limit>
          <lower>-0.523599</lower>
          <upper>0.523599</upper>
        </limit>
        <dynamics>
          <damping>1.000</damping>
        </dynamics>
	<use_parent_model_frame>1</use_parent_model_frame>
      </axis>
      <physics>
        <ode>
          <implicit_spring_damper>1</implicit_spring_damper>
        </ode>
      </physics>
    </joint>
    <link name='motor_1'>
      <pose>0.168 -0.22486 0.041843 0 -0 0</pose>
      <inertial>
        <pose frame=''>0 0 0 0 -0 0</pose>
        <mass>0.0054051</mass>
        <inertia>
          <ixx>9.75e-07</ixx>
          <ixy>0</ixy>
          <ixz>0</ixz>
          <iyy>0.000166704</iyy>
          <iyz>0</iyz>
          <izz>0.000167604</izz>
        </inertia>
      </inertial>
      <collision name='motor_1_collision'>
        <pose>0 0 0 0 -0 0</pose>
        <geometry>
	  <mesh>
            <scale>1 1 1</scale>
            <uri>model://tilt_rotor/meshes/propeller_front_right.STL</uri>
          </mesh>
        </geometry>
        <surface>
          <contact>
            <ode/>
          </contact>
          <friction>
            <ode/>
          </friction>
        </surface>
      </collision>
      <visual name='motor_1_visual'>
        <pose>0 0 0 0 -0 0</pose>
        <geometry>
          <mesh>
            <scale>1 1 1</scale>
            <uri>model://tilt_rotor/meshes/propeller_front_right.STL</uri>
          </mesh>
        </geometry>
        <material>
          <script>
            <name>Gazebo/Blue</name>
            <uri>__default__</uri>
          </script>
        </material>
      </visual>
      <gravity>1</gravity>
      <velocity_decay/>
      <self_collide>0</self_collide>
    </link>
    <joint name='motor_1_joint' type='revolute'>
      <child>motor_1</child>
      <parent>servo_motor_front_right</parent>
      <axis>
        <xyz>0 0 1</xyz>
        <limit>
          <lower>-1e+16</lower>
          <upper>1e+16</upper>
        </limit>
        <dynamics>
          <spring_reference>0</spring_reference>
          <spring_stiffness>0</spring_stiffness>
        </dynamics>
        <use_parent_model_frame>1</use_parent_model_frame>
      </axis>
    </joint>
    <link name='motor_2'>
       <pose>-0.358 0.22486 0.041843 0 -0 0</pose>
      <inertial>
	<pose frame=''>-0 0 0.006535 0 -0 0</pose> 
        <mass>0.0054051</mass>
        <inertia>
          <ixx>9.75e-07</ixx>
          <ixy>0</ixy>
          <ixz>0</ixz>
          <iyy>0.000166704</iyy>
          <iyz>0</iyz>
          <izz>0.000167604</izz>
        </inertia>
      </inertial>
      <collision name='motor_2_collision'>
        <pose>0 0 0 0 0 0</pose>
        <geometry>
          <mesh>
            <scale>1 1 1</scale>
            <uri>model://tilt_rotor/meshes/propeller_rear_left.STL</uri>
          </mesh>
        </geometry>
        <surface>
          <contact>
            <ode/>
          </contact>
          <friction>
            <ode/>
          </friction>
        </surface>
      </collision>
      <visual name='motor_2_visual'>
        <pose>0 0 0 0 0 0</pose>
        <geometry>
          <mesh>
            <scale>1 1 1</scale>
            <uri>model://tilt_rotor/meshes/propeller_rear_left.STL</uri>
          </mesh>
        </geometry>
        <material>
          <script>
            <name>Gazebo/Yellow</name>
            <uri>__default__</uri>
          </script>
        </material>
      </visual>
      <gravity>1</gravity>
      <velocity_decay/>
      <self_collide>0</self_collide>
    </link>
    <joint name='motor_2_joint' type='revolute'>
      <child>motor_2</child>
      <parent>base_link</parent>
      <axis>
        <xyz>0 0 1</xyz>
        <limit>
          <lower>-1e+16</lower>
          <upper>1e+16</upper>
        </limit>
        <dynamics>
          <spring_reference>0</spring_reference>
          <spring_stiffness>0</spring_stiffness>
        </dynamics>
        <use_parent_model_frame>1</use_parent_model_frame>
      </axis>
    </joint>
    <link name='motor_3'>
      <pose>0.168 0.22486 0.041843 0 -0 0</pose> 
      <inertial>
        <pose frame=''>0 0 0.006535 0 -0 0</pose> 
        <mass>0.0054054</mass>
        <inertia>
          <ixx>9.75e-07</ixx>
          <ixy>0</ixy>
          <ixz>0</ixz>
          <iyy>0.000166704</iyy>
          <iyz>0</iyz>
          <izz>0.000167604</izz>
        </inertia>
      </inertial>
      <collision name='motor_3_collision'>
        <pose>0 0 0 0 -0 0</pose>
        <geometry>
          <mesh>
            <scale>1 1 1</scale>
            <uri>model://tilt_rotor/meshes/propeller_front_left.STL</uri>
          </mesh>
        </geometry>
        <surface>
          <contact>
            <ode/>
          </contact>
          <friction>
            <ode/>
          </friction>
        </surface>
      </collision>
      <visual name='motor_3_visual'>
        <pose>0 0 0 0 -0 0</pose>
        <geometry>
          <mesh>
            <scale>1 1 1</scale>
            <uri>model://tilt_rotor/meshes/propeller_front_left.STL</uri>
          </mesh>
        </geometry>
        <material>
          <script>
            <name>Gazebo/Red</name>
            <uri>__default__</uri>
          </script>
        </material>
      </visual>
      <gravity>1</gravity>
      <velocity_decay/>
      <self_collide>0</self_collide>
    </link>
    <joint name='motor_3_joint' type='revolute'>
      <child>motor_3</child>
      <parent>servo_motor_front_left</parent>
      <axis>
        <xyz>0 0 1</xyz>
        <limit>
          <lower>-1e+16</lower>
          <upper>1e+16</upper>
        </limit>
        <dynamics>
          <spring_reference>0</spring_reference>
          <spring_stiffness>0</spring_stiffness>
        </dynamics>
        <use_parent_model_frame>1</use_parent_model_frame>
      </axis>
    </joint>
    <link name='motor_4'>
      <pose>-0.358 -0.22486 0.041843 0 -0 0</pose>
      <inertial>
        <pose frame=''>-0 0 0 0 -0 0</pose>
        <mass>0.005</mass>
        <inertia>
          <ixx>9.75e-07</ixx>
          <ixy>0</ixy>
          <ixz>0</ixz>
          <iyy>0.000166704</iyy>
          <iyz>0</iyz>
          <izz>0.000167604</izz>
        </inertia>
      </inertial>
      <collision name='motor_4_collision'>
        <pose>0 0 0 0 -0 0</pose>
        <geometry>
          <mesh>
            <scale>1 1 1</scale>
            <uri>model://tilt_rotor/meshes/propeller_rear_right.STL</uri>
          </mesh>
        </geometry>
        <surface>
          <contact>
            <ode/>
          </contact>
          <friction>
            <ode/>
          </friction>
        </surface>
      </collision>
      <visual name='motor_4_visual'>
        <pose>0 0 0 0 -0 0</pose>
        <geometry>
          <mesh>
            <scale>1 1 1</scale>
            <uri>model://tilt_rotor/meshes/propeller_rear_right.STL</uri>
          </mesh>
        </geometry>
        <material>
          <script>
            <name>Gazebo/DarkGrey</name>
            <uri>__default__</uri>
          </script>
        </material>
      </visual>
      <gravity>1</gravity>
      <velocity_decay/>
      <self_collide>0</self_collide>
    </link>
    <joint name='motor_4_joint' type='revolute'>
      <child>motor_4</child>
      <parent>base_link</parent>
      <axis>
        <xyz>0 0 1</xyz>
        <limit>
          <lower>-1e+16</lower>
          <upper>1e+16</upper>
        </limit>
        <dynamics>
          <spring_reference>0</spring_reference>
          <spring_stiffness>0</spring_stiffness>
        </dynamics>
        <use_parent_model_frame>1</use_parent_model_frame>
      </axis>
    </joint>

    <link name="left_elevon">
      <pose frame=''>-0.16997 0.2 0.005812 0 -0 0</pose>
      <inertial>
 	<pose frame=''>-0.016756 0.24939 -0.003295 0 -0 0</pose>
        <mass>0.0038016</mass>
        <inertia>
	  <ixx>0.000001</ixx>
          <ixy>0.0</ixy>
          <iyy>0.000001</iyy>
          <ixz>0.0</ixz>
          <iyz>0.0</iyz>
          <izz>0.000001</izz>
        </inertia>
      </inertial>
      <visual name='left_elevon_visual'>
        <pose>0 0 0 0 -0 0</pose>
        <geometry>
          <mesh>
            <scale>1 1 1</scale>
            <uri>model://tilt_rotor/meshes/aileron_left.STL</uri>
          </mesh>
        </geometry>
        <material>
          <script>
            <name>Gazebo/White</name>
            <uri>__default__</uri>
          </script>
        </material>
      </visual>
    </link>
    <link name="right_elevon">
      <pose frame=''>-0.16997 -0.2 0.005812 0 -0 0</pose>
      <inertial>
	<pose frame=''>-0.016759 -0.25061 -0.003282 0 -0 0</pose>
        <mass>0.0038016</mass>
        <inertia>
          <ixx>0.000001</ixx>
          <ixy>0.0</ixy>
          <iyy>0.000001</iyy>
          <ixz>0.0</ixz>
          <iyz>0.0</iyz>
          <izz>0.000001</izz>
        </inertia>
      </inertial>
      <visual name='right_elevon_visual'>
        <pose frame=''>0 0 0 0 -0 0</pose>
        <geometry>
          <mesh>
            <scale>1 1 1</scale>
            <uri>model://tilt_rotor/meshes/aileron_right.STL</uri>
          </mesh>
        </geometry>
        <material>
          <script>
            <name>Gazebo/White</name>
            <uri>__default__</uri>
          </script>
        </material>
      </visual>
    </link>
    <joint name='left_elevon_joint' type='revolute'>
      <parent>base_link</parent>
      <child>left_elevon</child>
      <axis>
        <xyz>0 1 0</xyz>
        <limit>
          <lower>-0.5236</lower>
          <upper>0.5236</upper>
        </limit>
        <dynamics>
          <damping>1.000</damping>
        </dynamics>
      </axis>
      <physics>
        <ode>
          <implicit_spring_damper>1</implicit_spring_damper>
        </ode>
      </physics>
    </joint>
    <joint name='right_elevon_joint' type='revolute'>
      <parent>base_link</parent>
      <child>right_elevon</child>
      <axis>
        <xyz>0 1 0</xyz>
        <limit>
          <lower>-0.5236</lower>
          <upper>0.5236</upper>
        </limit>
        <dynamics>
          <damping>1.000</damping>
        </dynamics>
      </axis>
      <physics>
        <ode>
          <implicit_spring_damper>1</implicit_spring_damper>
        </ode>
      </physics>
    </joint>

    <plugin name="left_wing" filename="libLiftDragPlugin.so">
      <a0>0.05984281113</a0>
      <cla>4.752798721</cla>
      <cda>0.6417112299</cda>
      <cma>-1.8</cma>
      <alpha_stall>0.3391428111</alpha_stall>
      <cla_stall>-3.85</cla_stall>
      <cda_stall>-0.9233984055</cda_stall>
      <cma_stall>0</cma_stall>
      <cp>-0.05 0.3 0.05</cp>
      <area>0.12</area>
      <air_density>1.2041</air_density>
      <forward>1 0 0</forward>
      <upward>0 0 1</upward>
      <link_name>base_link</link_name>
      <control_joint_name>
        left_elevon_joint
      </control_joint_name>
      <control_joint_rad_to_cl>-0.5</control_joint_rad_to_cl>
    </plugin>
    <plugin name="right_wing" filename="libLiftDragPlugin.so">
      <a0>0.05984281113</a0>
      <cla>4.752798721</cla>
      <cda>0.6417112299</cda>
      <cma>-1.8</cma>
      <alpha_stall>0.3391428111</alpha_stall>
      <cla_stall>-3.85</cla_stall>
      <cda_stall>-0.9233984055</cda_stall>
      <cma_stall>0</cma_stall>
      <cp>-0.05 -0.3 0.05</cp>
      <area>0.12</area>
      <air_density>1.2041</air_density>
      <forward>1 0 0</forward>
      <upward>0 0 1</upward>
      <link_name>base_link</link_name>
      <control_joint_name>
        right_elevon_joint
      </control_joint_name>
      <control_joint_rad_to_cl>-0.5</control_joint_rad_to_cl>
    </plugin>
     
<plugin name="left_tail" filename="libLiftDragPlugin.so">
      <a0>0.0</a0>
      <cla>4.752798721</cla>
      <cda>0.6417112299</cda>
      <cma>-1.8</cma>
      <alpha_stall>0.3391428111</alpha_stall>
      <cla_stall>-3.85</cla_stall>
      <cda_stall>-0.9233984055</cda_stall>
      <cma_stall>0</cma_stall>
      <cp>-0.5 0 0.05</cp>
      <area>0.02</area>
      <air_density>1.2041</air_density>
      <forward>1 0 0</forward>
      <upward>0 1 0</upward>
      <link_name>base_link</link_name>
      <control_joint_name>
        ruddervator_left_joint
      </control_joint_name>
      <control_joint_rad_to_cl>-4.0</control_joint_rad_to_cl>
    </plugin>

    <plugin name="right_tail" filename="libLiftDragPlugin.so">
      <a0>0.0</a0>
      <cla>4.752798721</cla>
      <cda>0.6417112299</cda>
      <cma>-1.8</cma>
      <alpha_stall>0.3391428111</alpha_stall>
      <cla_stall>-3.85</cla_stall>
      <cda_stall>-0.9233984055</cda_stall>
      <cma_stall>0</cma_stall>
      <cp>-0.5 0 0.05</cp>
      <area>0.02</area>
      <air_density>1.2041</air_density>
      <forward>1 0 0</forward>
      <upward>0 1 0</upward>
      <link_name>base_link</link_name>
      <control_joint_name>
        ruddervator_right_joint
      </control_joint_name>
      <control_joint_rad_to_cl>-4.0</control_joint_rad_to_cl>
    </plugin> 
    
    <plugin name="motor_1_blade_1" filename="libLiftDragPlugin.so">
      <a0>0.3</a0>
      <alpha_stall>1.4</alpha_stall>
      <cla>4.2500</cla>
      <cda>0.10</cda>
      <cma>0.00</cma>
      <cla_stall>-0.025</cla_stall>
      <cda_stall>0.0</cda_stall>
      <cma_stall>0.0</cma_stall>
      <area>0.005</area>
      <air_density>1.2041</air_density>
       <cp>0 0.063 0</cp>
      <forward>-1 0 0</forward>
      <upward>0 0 1</upward>
      <link_name>motor_1</link_name>
    </plugin>
    <plugin name="motor_1_blade_2" filename="libLiftDragPlugin.so">
      <a0>0.3</a0>
      <alpha_stall>1.4</alpha_stall>
      <cla>4.2500</cla>
      <cda>0.10</cda>
      <cma>0.00</cma>
      <cda_stall>0.0</cda_stall>
      <cla_stall>-0.025</cla_stall>
      <cma_stall>0.0</cma_stall>
      <area>0.005</area>
      <air_density>1.2041</air_density>
      <cp>0  -0.063 0</cp>
      <forward>1 0 0</forward>
      <upward>0 0 1</upward>
      <link_name>motor_1</link_name>
    </plugin>

    <plugin name="motor_2_blade_1" filename="libLiftDragPlugin.so">
      <a0>0.3</a0>
      <alpha_stall>1.4</alpha_stall>
      <cla>4.2500</cla>
      <cda>0.10</cda>
      <cma>0.00</cma>
      <cla_stall>-0.025</cla_stall>
      <cda_stall>0.0</cda_stall>
      <cma_stall>0.0</cma_stall>
      <area>0.005</area>
      <air_density>1.2041</air_density>
       <cp>0 0.063 0</cp>
      <forward>-1 0 0</forward>
      <upward>0 0 1</upward>
      <link_name>motor_2</link_name>
    </plugin>
    <plugin name="motor_2_blade_2" filename="libLiftDragPlugin.so">
      <a0>0.3</a0>
      <alpha_stall>1.4</alpha_stall>
      <cla>4.2500</cla>
      <cda>0.10</cda>
      <cma>0.00</cma>
      <cda_stall>0.0</cda_stall>
      <cla_stall>-0.025</cla_stall>
      <cma_stall>0.0</cma_stall>
      <area>0.005</area>
      <air_density>1.2041</air_density>
      <cp>0  -0.063 0</cp>
      <forward>1 0 0</forward>
      <upward>0 0 1</upward>
      <link_name>motor_2</link_name>
    </plugin>

    <plugin name="motor_3_blade_1" filename="libLiftDragPlugin.so">
      <a0>0.3</a0>
      <alpha_stall>1.4</alpha_stall>
      <cla>4.2500</cla>
      <cda>0.10</cda>
      <cma>0.00</cma>
      <cla_stall>-0.025</cla_stall>
      <cda_stall>0.0</cda_stall>
      <cma_stall>0.0</cma_stall>
      <area>0.005</area>
      <air_density>1.2041</air_density>
       <cp>0 0.063 0</cp>
      <forward>1 0 0</forward>
      <upward>0 0 1</upward>
      <link_name>motor_3</link_name>
    </plugin>
    <plugin name="motor_3_blade_2" filename="libLiftDragPlugin.so">
      <a0>0.3</a0>
      <alpha_stall>1.4</alpha_stall>
      <cla>4.2500</cla>
      <cda>0.10</cda>
      <cma>0.00</cma>
      <cda_stall>0.0</cda_stall>
      <cla_stall>-0.025</cla_stall>
      <cma_stall>0.0</cma_stall>
      <area>0.005</area>
      <air_density>1.2041</air_density>
      <cp>0  -0.063 0</cp>
      <forward>-1 0 0</forward>
      <upward>0 0 1</upward>
      <link_name>motor_3</link_name>
    </plugin>

    <plugin name="motor_4_blade_1" filename="libLiftDragPlugin.so">
      <a0>0.3</a0>
      <alpha_stall>1.4</alpha_stall>
      <cla>4.2500</cla>
      <cda>0.10</cda>
      <cma>0.00</cma>
      <cla_stall>-0.025</cla_stall>
      <cda_stall>0.0</cda_stall>
      <cma_stall>0.0</cma_stall>
      <area>0.005</area>
      <air_density>1.2041</air_density>
      <cp>0 0.063 0</cp>
      <forward>1 0 0</forward>
      <upward>0 0 1</upward>
      <link_name>motor_4</link_name>
    </plugin>
    <plugin name="motor_4_blade_2" filename="libLiftDragPlugin.so">
      <a0>0.3</a0>
      <alpha_stall>1.4</alpha_stall>
      <cla>4.2500</cla>
      <cda>0.10</cda>
      <cma>0.00</cma>
      <cda_stall>0.0</cda_stall>
      <cla_stall>-0.025</cla_stall>
      <cma_stall>0.0</cma_stall>
      <area>0.005</area>
      <air_density>1.2041</air_density>
      <cp>0  -0.063 0</cp>
      <forward>-1 0 0</forward>
      <upward>0 0 1</upward>
      <link_name>motor_4</link_name>
    </plugin>
    <!-- <plugin name="propeller_blade_1" filename="libLiftDragPlugin.so">
      <a0>0.30</a0>
      <alpha_stall>1.4</alpha_stall>
      <cla>4.2500</cla>
      <cda>0.10</cda>
      <cma>0.00</cma>
      <cla_stall>-0.025</cla_stall>
      <cda_stall>0.0</cda_stall>
      <cma_stall>0.0</cma_stall>
      <area>0.002</area>
      <air_density>1.2041</air_density>
      <cp>0.084 0 0</cp>
      <forward>0 -1 0</forward>
      <upward>0 0 -1</upward>
      <link_name>rotor_puller</link_name>
    </plugin>
    <plugin name="propeller_blade_2" filename="libLiftDragPlugin.so">
      <a0>0.30</a0>
      <alpha_stall>1.4</alpha_stall>
      <cla>4.2500</cla>
      <cda>0.10</cda>
      <cma>0.00</cma>
      <cla_stall>-0.025</cla_stall>
      <cda_stall>0.0</cda_stall>
      <cma_stall>0.0</cma_stall>
      <area>0.002</area>
      <air_density>1.2041</air_density>
      <cp>-0.084 0 0</cp>
      <forward>0 1 0</forward>
      <upward>0 0 -1</upward>
      <link_name>rotor_puller</link_name>
    </plugin> -->
    <!-- <plugin name='puller' filename='libgazebo_motor_model.so'>
      <robotNamespace></robotNamespace>
      <jointName>rotor_puller_joint</jointName>
      <linkName>rotor_puller</linkName>
      <turningDirection>cw</turningDirection>
      <timeConstantUp>0.0125</timeConstantUp>
      <timeConstantDown>0.025</timeConstantDown>
      <maxRotVelocity>3500</maxRotVelocity>
      <motorConstant>8.54858e-06</motorConstant>
      <momentConstant>0.01</momentConstant>
      <commandSubTopic>/gazebo/command/motor_speed</commandSubTopic>
      <motorNumber>4</motorNumber>
      <rotorDragCoefficient>8.06428e-05</rotorDragCoefficient>
      <rollingMomentCoefficient>1e-06</rollingMomentCoefficient>
      <motorSpeedPubTopic>/motor_speed/4</motorSpeedPubTopic>
      <rotorVelocitySlowdownSim>20</rotorVelocitySlowdownSim>
    </plugin> -->
    <!-- <plugin name='gazebo_imu_plugin' filename='libgazebo_imu_plugin.so'>
      <robotNamespace></robotNamespace>
      <linkName>standard_vtol/imu_link</linkName>
      <imuTopic>/imu</imuTopic>
      <gyroscopeNoiseDensity>0.0003394</gyroscopeNoiseDensity>
      <gyroscopeRandomWalk>3.8785e-05</gyroscopeRandomWalk>
      <gyroscopeBiasCorrelationTime>1000.0</gyroscopeBiasCorrelationTime>
      <gyroscopeTurnOnBiasSigma>0.0087</gyroscopeTurnOnBiasSigma>
      <accelerometerNoiseDensity>0.004</accelerometerNoiseDensity>
      <accelerometerRandomWalk>0.006</accelerometerRandomWalk>
      <accelerometerBiasCorrelationTime>300.0</accelerometerBiasCorrelationTime>
      <accelerometerTurnOnBiasSigma>0.196</accelerometerTurnOnBiasSigma>
    </plugin> -->
    <!--
    <plugin name='wind_plugin' filename='libgazebo_wind_plugin.so'>
      <frameId>base_link</frameId>
      <linkName>base_link</linkName>
      <robotNamespace/>
      <xyzOffset>1 0 0</xyzOffset>
      <windDirection>0 1 0</windDirection>
      <windForceMean>0.7</windForceMean>
      <windGustDirection>0 0 0</windGustDirection>
      <windGustDuration>0</windGustDuration>
      <windGustStart>0</windGustStart>
      <windGustForceMean>0</windGustForceMean>
    </plugin>
    -->
    <!-- <plugin name="gps_plugin" filename="libgazebo_gps_plugin.so">
        <robotNamespace></robotNamespace>
        <gpsNoise>true</gpsNoise>
    </plugin> -->
    <!-- <plugin name='mavlink_interface' filename='libgazebo_mavlink_interface.so'>
      <robotNamespace></robotNamespace>
      <imuSubTopic>/imu</imuSubTopic>
      <gpsSubTopic>/gps</gpsSubTopic>
      <mavlink_addr>INADDR_ANY</mavlink_addr>
      <mavlink_udp_port>14560</mavlink_udp_port>
      <serialEnabled>false</serialEnabled>
      <serialDevice>/dev/ttyACM0</serialDevice>
      <baudRate>921600</baudRate>
      <qgc_addr>INADDR_ANY</qgc_addr>
      <qgc_udp_port>14550</qgc_udp_port>
      <hil_mode>false</hil_mode>
      <hil_state_level>false</hil_state_level>
      <motorSpeedCommandPubTopic>/gazebo/command/motor_speed</motorSpeedCommandPubTopic>
      <control_channels>
        <channel name="rotor0">
          <input_index>0</input_index>
          <input_offset>0</input_offset>
          <input_scaling>1500</input_scaling>
          <zero_position_disarmed>0</zero_position_disarmed>
          <zero_position_armed>0</zero_position_armed>
          <joint_control_type>velocity</joint_control_type>
          <joint_name>rotor_0_joint</joint_name>
        </channel>
        <channel name="rotor1">
          <input_index>1</input_index>
          <input_offset>0</input_offset>
          <input_scaling>1500</input_scaling>
          <zero_position_disarmed>0</zero_position_disarmed>
          <zero_position_armed>0</zero_position_armed>
          <joint_control_type>velocity</joint_control_type>
          <joint_name>rotor_1_joint</joint_name>
        </channel>
        <channel name="rotor2">
          <input_index>2</input_index>
          <input_offset>0</input_offset>
          <input_scaling>1500</input_scaling>
          <zero_position_disarmed>0</zero_position_disarmed>
          <zero_position_armed>0</zero_position_armed>
          <joint_control_type>velocity</joint_control_type>
          <joint_name>rotor_2_joint</joint_name>
        </channel>
        <channel name="rotor3">
          <input_index>3</input_index>
          <input_offset>0</input_offset>
          <input_scaling>1500</input_scaling>
          <zero_position_disarmed>0</zero_position_disarmed>
          <zero_position_armed>0</zero_position_armed>
          <joint_control_type>velocity</joint_control_type>
          <joint_name>rotor_3_joint</joint_name>
        </channel>
        <channel name="rotor4">
          <input_index>4</input_index>
          <input_offset>0</input_offset>
          <input_scaling>3500</input_scaling>
          <zero_position_disarmed>0</zero_position_disarmed>
          <zero_position_armed>0</zero_position_armed>
          <joint_control_type>velocity</joint_control_type>
          <joint_name>rotor_puller_joint</joint_name>
        </channel>
        <channel name="left_elevon">
          <input_index>5</input_index>
          <input_offset>0</input_offset>
          <input_scaling>1</input_scaling>
          <zero_position_disarmed>0</zero_position_disarmed>
          <zero_position_armed>0</zero_position_armed>
          <joint_control_type>position_kinematic</joint_control_type>
          <joint_name>left_elevon_joint</joint_name>
        </channel>
        <channel name="right_elevon">
          <input_index>6</input_index>
          <input_offset>0</input_offset>
          <input_scaling>1</input_scaling>
          <zero_position_disarmed>0</zero_position_disarmed>
          <zero_position_armed>0</zero_position_armed>
          <joint_control_type>position_kinematic</joint_control_type>
          <joint_name>right_elevon_joint</joint_name>
        </channel>
        <channel name="elevator">
          <input_index>7</input_index>
          <input_offset>0</input_offset>
          <input_scaling>1</input_scaling>
          <zero_position_disarmed>0</zero_position_disarmed>
          <zero_position_armed>0</zero_position_armed>
          <joint_control_type>position_kinematic</joint_control_type>
          <joint_name>elevator_joint</joint_name>
        </channel>
      </control_channels>
      <left_elevon_joint>
        left_elevon_joint
      </left_elevon_joint>
      <right_elevon_joint>
        right_elevon_joint
      </right_elevon_joint>
      <elevator_joint>
        elevator_joint
      </elevator_joint>
    </plugin> -->
    <plugin name="arducopter_plugin" filename="libArduPilotPlugin.so">
      <fdm_addr>127.0.0.1</fdm_addr>
      <fdm_port_in>9002</fdm_port_in>
      <fdm_port_out>9003</fdm_port_out>
      <!--
          Require by APM :
          Only change model and gazebo from XYZ to XY-Z coordinates
      -->
      <modelXYZToAirplaneXForwardZDown>0 0 0 3.141593 0 0</modelXYZToAirplaneXForwardZDown>
      <gazeboXYZToNED>0 0 0 3.141593 0 0</gazeboXYZToNED>
      <imuName>tilt_rotor/imu_link::imu_sensor</imuName>
      <connectionTimeoutMaxCount>5</connectionTimeoutMaxCount>
      <control channel="0">
        <multiplier>-1</multiplier>
        <offset>-0.5</offset>
        <type>POSITION</type>
        <p_gain>10.0</p_gain>
        <i_gain>0</i_gain>
        <d_gain>0</d_gain>
        <i_max>0</i_max>
        <i_min>0</i_min>
        <cmd_max>2.0</cmd_max>
        <cmd_min>-2.0</cmd_min>
        <jointName>servo_front_left_joint</jointName>
      </control>
      <control channel="1">
        <multiplier>-1</multiplier>
        <offset>-0.5</offset>
        <type>POSITION</type>
        <p_gain>10.0</p_gain>
        <i_gain>0</i_gain>
        <d_gain>0</d_gain>
        <i_max>0</i_max>
        <i_min>0</i_min>
        <cmd_max>2.0</cmd_max>
        <cmd_min>-2.0</cmd_min>
        <jointName>servo_front_right_joint</jointName>
      </control>

      <control channel="4">
        <multiplier>1000</multiplier>
        <offset>0</offset>
        <type>VELOCITY</type>
        <p_gain>0.2</p_gain>
        <i_gain>0.2</i_gain>
        <d_gain>0.0</d_gain>
        <i_max>0</i_max>
        <i_min>0</i_min>
        <cmd_max>2.5</cmd_max>
        <cmd_min>-2.5</cmd_min>
        <jointName>motor_1_joint</jointName>
        <rotorVelocitySlowdownSim>1</rotorVelocitySlowdownSim>
      </control>

      <control channel="5">
        <multiplier>1000</multiplier>
        <offset>0</offset>
        <type>VELOCITY</type>
        <p_gain>0.2</p_gain>
        <i_gain>0.2</i_gain>
        <d_gain>0.0</d_gain>
        <i_max>0</i_max>
        <i_min>0</i_min>
        <cmd_max>2.5</cmd_max>
        <cmd_min>-2.5</cmd_min>
        <jointName>motor_2_joint</jointName>
        <rotorVelocitySlowdownSim>1</rotorVelocitySlowdownSim>
      </control>

      <control channel="6">
        <multiplier>-1000</multiplier>
        <offset>0</offset>
        <type>VELOCITY</type>
        <p_gain>0.2</p_gain>
        <i_gain>0.2</i_gain>
        <d_gain>0.0</d_gain>
        <i_max>0</i_max>
        <i_min>0</i_min>
        <cmd_max>2.5</cmd_max>
        <cmd_min>-2.5</cmd_min>
        <jointName>motor_3_joint</jointName>
        <rotorVelocitySlowdownSim>1</rotorVelocitySlowdownSim>
      </control>

      <control channel="7">
        <multiplier>-1000</multiplier>
        <offset>0</offset>
        <type>VELOCITY</type>
        <p_gain>0.2</p_gain>
        <i_gain>0.2</i_gain>
        <d_gain>0.0</d_gain>
        <i_max>0</i_max>
        <i_min>0</i_min>
        <cmd_max>2.5</cmd_max>
        <cmd_min>-2.5</cmd_min>
        <jointName>motor_4_joint</jointName>
        <rotorVelocitySlowdownSim>1</rotorVelocitySlowdownSim>
      </control>
<!-- 
      <control channel="8">
          <multiplier>1</multiplier>
          <offset>-0.5</offset>
          <type>POSITION</type>
          <p_gain>2.5</p_gain>
          <i_gain>0</i_gain>
          <d_gain>0.1</d_gain>
          <i_max>0</i_max>
          <i_min>0</i_min>
          <cmd_max>1</cmd_max>
          <cmd_min>-1</cmd_min>
        <jointName>ruddervator_left_joint</jointName>
      </control> -->

      <control channel="9">
          <multiplier>1</multiplier>
          <offset>-0.5</offset>
          <type>POSITION</type>
          <p_gain>2.5</p_gain>
          <i_gain>0</i_gain>
          <d_gain>0</d_gain>
          <i_max>0</i_max>
          <i_min>0</i_min>
          <cmd_max>1</cmd_max>
          <cmd_min>-1</cmd_min>
        <jointName>left_elevon_joint</jointName>
      </control> 

      <control channel="10">
        <multiplier>1</multiplier>
        <offset>-0.5</offset>
        <type>POSITION</type>
        <p_gain>2.5</p_gain>
        <i_gain>0</i_gain>
        <d_gain>0</d_gain>
        <i_max>0</i_max>
        <i_min>0</i_min>
        <cmd_max>1</cmd_max>
        <cmd_min>-1</cmd_min>
        <jointName>right_elevon_joint</jointName>
      </control> 
<!-- 
      <control channel="11">
          <multiplier>1</multiplier>
          <offset>-0.5</offset>
          <type>POSITION</type>
          <p_gain>2.5</p_gain>
          <i_gain>0</i_gain>
          <d_gain>0.1</d_gain>
          <i_max>0</i_max>
          <i_min>0</i_min>
          <cmd_max>1</cmd_max>
          <cmd_min>-1</cmd_min>
        <jointName>ruddervator_right_joint</jointName>
      </control> -->

    </plugin>

    <static>0</static>
  </model>
</sdf>
